Workbook
Name Average: OFFSET(Calculations!$AQ$11,,,Main!$C$29,1)
Name Batteries: OFFSET(TestSorting!$T$2,0,0,TestSorting!$S$1-1,1)
Name Errors: OFFSET(Calculations!$AL$11,0,0,Main!$C$29,1)
Name Expect2: OFFSET(Calculations!$AI$11,,,Main!$C$29,1)
Name Expected: OFFSET(Calculations!$AH$11,,,Main!$C$29,1)
Name Extremely_High: OFFSET(Calculations!$AU$11,,,Main!$C$29,1)
Name Extremely_Low: OFFSET(Calculations!$AM$11,,,Main!$C$29,1)
Name Flynn: Main!$A$26
Name High: OFFSET(Calculations!$AS$11,,,Main!$C$29,1)
Name High_Average: OFFSET(Calculations!$AR$11,,,Main!$C$29,1)
Name Low: OFFSET(Calculations!$AO$11,,,Main!$C$29,1)
Name Low_Average: OFFSET(Calculations!$AP$11,,,Main!$C$29,1)
Name Observed: OFFSET(Calculations!$AG$11,,,Main!$C$29,1)
Name SEE: OFFSET(Calculations!$AJ$11,0,0,Main!$C$29,1)
Name Subtests: OFFSET(Calculations!$AK$11,,,Main!$C$29,1)
Name TestList: OFFSET(Tests!$J$3,0,0,Tests!#REF!,1)
Name Very_High: OFFSET(Calculations!$AT$11,,,Main!$C$29,1)
Name Very_Low: OFFSET(Calculations!$AN$11,,,Main!$C$29,1)

Sheet Main
C1: Default Flynn Effect Size (per decade) | F1: 2.94 | R1: Default Reliability | S1: 0.96 | Z1: Default Correlations in Red, using equations from Breit, M., Scherrer, V., Tucker-Drob, E. M., & Preckel, F. (2024). The stability of cognitive abilities: A meta-analytic review of longitudinal studies. Psychological Bulletin. https://doi.org/10.1037/bul0000425
B2: Battery | C2: Edition | D2: Scores | E2: Weight | F2: Flynn Effect | G2: Age at Testing | H2: Year Tested | I2: Year Normed | J2: Years Elapsed | K2: Corrected Score | L2: Uncorrected Score | M2: Expected Score | N2: Deviation from Expected | O2: p(Deviation) | P2: Size of Deviation | Q2: Mean | R2: SD | S2: Reliability | T2: Family | Y2: Correlations | Z2: 1 | AA2: 2 | AB2: 3 | AC2: 4 | AD2: 5 | AE2: 6 | AF2: 7 | AG2: 8 | AH2: 9 | AI2: 10 | AJ2: 11 | AK2: 12 | AL2: 13 | AM2: 14 | AN2: 15 | AO2: 16 | AP2: 17 | AQ2: 18 | AR2: 19 | AS2: 20
B3: Wechsler Intelligence Scale for Children | C3: WISC-R (1974) | D3: 77 | E3: 1 | G3: 10 | H3: 1982 | I3: =IF($C3="","",MIN(INDEX(Tests!E$3:E$499,MATCH($C3,Tests!$J$3:$J$499,0)),INDEX(Tests!F$3:F$499,MATCH($C3,Tests!$J$3:$J$499,0)))) -> 1972 | J3: =IF(OR(ISBLANK(H3),ISBLANK(I3)),"",H3-I3) -> 10 | K3: =IF(OR(J3="",J3<0),"",-0.1*IF(ISBLANK(F3),F$1,F3)*J3+L3) -> 74.06 | L3: =IF(OR(B3="",C3="",D3=""),"",15*(D3-Q3)/R3+100) -> 77 | M3: =IF(ISNA(Calculations!N11),"",Calculations!N11) -> 70.641913 | N3: =IF(Calculations!Z11="","",Calculations!Z11-M3) -> 3.4180871 | O3: =IF(OR(Calculations!Z11="",ISNA(Calculations!Y11)),"",Calculations!Y11) -> 0.36 | P3: {=IF(O3="","",INDEX(Calculations!$E$33:$E$41,1+SUM(--(Calculations!K11>Calculations!$C$34:$C$41)),1))} -> Average-sized deviation | Q3: =IF($C3="","",INDEX(Tests!G$3:G$499,MATCH($C3,Tests!$J$3:$J$499,0))) -> 100 | R3: =IF($C3="","",INDEX(Tests!H$3:H$499,MATCH($C3,Tests!$J$3:$J$499,0))) -> 15 | S3: =Calculations!AB11 -> 0.96 | T3: =IF($C3="","",INDEX(Tests!C$3:C$499,MATCH($C3,Tests!$J$3:$J$499,0))) -> Wechsler | Y3: {=IF(C3:C22="",TRANSPOSE(Z2:AS2),TRANSPOSE(Z2:AS2)&". "&C3:C22)} -> 1. WISC-R (1974) | Z3: 1 | AA3: =IF(Blanks!C2,INDEX(Calculations!$C$88:$V$107,COLUMN(B1),ROW(B1)),INDEX($Z$3:$AS$22,COLUMN(B1),ROW(B1))) -> 0.84139727 | AB3: =IF(Blanks!D2,INDEX(Calculations!$C$88:$V$107,COLUMN(C1),ROW(C1)),INDEX($Z$3:$AS$22,COLUMN(C1),ROW(C1))) -> 0.68839623 | AC3: =IF(Blanks!E2,INDEX(Calculations!$C$88:$V$107,COLUMN(D1),ROW(D1)),INDEX($Z$3:$AS$22,COLUMN(D1),ROW(D1))) -> 0.57392126 | AD3: =IF(Blanks!F2,INDEX(Calculations!$C$88:$V$107,COLUMN(E1),ROW(E1)),INDEX($Z$3:$AS$22,COLUMN(E1),ROW(E1))) -> 0.67716731 | AE3: =IF(Blanks!G2,INDEX(Calculations!$C$88:$V$107,COLUMN(F1),ROW(F1)),INDEX($Z$3:$AS$22,COLUMN(F1),ROW(F1))) | AF3: =IF(Blanks!H2,INDEX(Calculations!$C$88:$V$107,COLUMN(G1),ROW(G1)),INDEX($Z$3:$AS$22,COLUMN(G1),ROW(G1))) | AG3: =IF(Blanks!I2,INDEX(Calculations!$C$88:$V$107,COLUMN(H1),ROW(H1)),INDEX($Z$3:$AS$22,COLUMN(H1),ROW(H1))) | AH3: =IF(Blanks!J2,INDEX(Calculations!$C$88:$V$107,COLUMN(I1),ROW(I1)),INDEX($Z$3:$AS$22,COLUMN(I1),ROW(I1))) | ... AS3: =IF(Blanks!U2,INDEX(Calculations!$C$88:$V$107,COLUMN(T1),ROW(T1)),INDEX($Z$3:$AS$22,COLUMN(T1),ROW(T1)))
B4: Wechsler Intelligence Scale for Children | C4: WISC-R (1974) | D4: 71 | E4: 1 | G4: 11 | H4: 1983 | I4: =IF($C4="","",MIN(INDEX(Tests!E$3:E$499,MATCH($C4,Tests!$J$3:$J$499,0)),INDEX(Tests!F$3:F$499,MATCH($C4,Tests!$J$3:$J$499,0)))) -> 1972 | J4: =IF(OR(ISBLANK(H4),ISBLANK(I4)),"",H4-I4) -> 11 | K4: =IF(OR(J4="",J4<0),"",-0.1*IF(ISBLANK(F4),F$1,F4)*J4+L4) -> 67.766 | L4: =IF(OR(B4="",C4="",D4=""),"",15*(D4-Q4)/R4+100) -> 71 | M4: =IF(ISNA(Calculations!N12),"",Calculations!N12) -> 70.415801 | N4: =IF(Calculations!Z12="","",Calculations!Z12-M4) -> -2.6498011 | O4: =IF(OR(Calculations!Z12="",ISNA(Calculations!Y12)),"",Calculations!Y12) -> 0.29 | P4: {=IF(O4="","",INDEX(Calculations!$E$33:$E$41,1+SUM(--(Calculations!K12>Calculations!$C$34:$C$41)),1))} -> Average-sized deviation | Q4: =IF($C4="","",INDEX(Tests!G$3:G$499,MATCH($C4,Tests!$J$3:$J$499,0))) -> 100 | R4: =IF($C4="","",INDEX(Tests!H$3:H$499,MATCH($C4,Tests!$J$3:$J$499,0))) -> 15 | S4: =Calculations!AB12 -> 0.96 | T4: =IF($C4="","",INDEX(Tests!C$3:C$499,MATCH($C4,Tests!$J$3:$J$499,0))) -> Wechsler | Y4: 2. WISC-R (1974) | AA4: 1 | AB4: =IF(Blanks!D3,INDEX(Calculations!$C$88:$V$107,COLUMN(C2),ROW(C2)),INDEX($Z$3:$AS$22,COLUMN(C2),ROW(C2))) -> 0.69917339 | AC4: =IF(Blanks!E3,INDEX(Calculations!$C$88:$V$107,COLUMN(D2),ROW(D2)),INDEX($Z$3:$AS$22,COLUMN(D2),ROW(D2))) -> 0.58314837 | AD4: =IF(Blanks!F3,INDEX(Calculations!$C$88:$V$107,COLUMN(E2),ROW(E2)),INDEX($Z$3:$AS$22,COLUMN(E2),ROW(E2))) -> 0.68628285 | AE4: =IF(Blanks!G3,INDEX(Calculations!$C$88:$V$107,COLUMN(F2),ROW(F2)),INDEX($Z$3:$AS$22,COLUMN(F2),ROW(F2))) | AF4: =IF(Blanks!H3,INDEX(Calculations!$C$88:$V$107,COLUMN(G2),ROW(G2)),INDEX($Z$3:$AS$22,COLUMN(G2),ROW(G2))) | AG4: =IF(Blanks!I3,INDEX(Calculations!$C$88:$V$107,COLUMN(H2),ROW(H2)),INDEX($Z$3:$AS$22,COLUMN(H2),ROW(H2))) | AH4: =IF(Blanks!J3,INDEX(Calculations!$C$88:$V$107,COLUMN(I2),ROW(I2)),INDEX($Z$3:$AS$22,COLUMN(I2),ROW(I2))) | AI4: =IF(Blanks!K3,INDEX(Calculations!$C$88:$V$107,COLUMN(J2),ROW(J2)),INDEX($Z$3:$AS$22,COLUMN(J2),ROW(J2))) | ... AS4: =IF(Blanks!U3,INDEX(Calculations!$C$88:$V$107,COLUMN(T2),ROW(T2)),INDEX($Z$3:$AS$22,COLUMN(T2),ROW(T2)))
B5: Wechsler Adult Intelligence Scale | C5: WAIS-III (1997) | D5: 73 | E5: 1 | G5: 30 | H5: 2002 | I5: =IF($C5="","",MIN(INDEX(Tests!E$3:E$499,MATCH($C5,Tests!$J$3:$J$499,0)),INDEX(Tests!F$3:F$499,MATCH($C5,Tests!$J$3:$J$499,0)))) -> 1995 | J5: =IF(OR(ISBLANK(H5),ISBLANK(I5)),"",H5-I5) -> 7 | K5: =IF(OR(J5="",J5<0),"",-0.1*IF(ISBLANK(F5),F$1,F5)*J5+L5) -> 70.942 | L5: =IF(OR(B5="",C5="",D5=""),"",15*(D5-Q5)/R5+100) -> 73 | M5: =IF(ISNA(Calculations!N13),"",Calculations!N13) -> 70.873923 | N5: =IF(Calculations!Z13="","",Calculations!Z13-M5) -> 0.068076616 | O5: =IF(OR(Calculations!Z13="",ISNA(Calculations!Y13)),"",Calculations!Y13) -> 0.007 | P5: {=IF(O5="","",INDEX(Calculations!$E$33:$E$41,1+SUM(--(Calculations!K13>Calculations!$C$34:$C$41)),1))} -> Very small deviation | Q5: =IF($C5="","",INDEX(Tests!G$3:G$499,MATCH($C5,Tests!$J$3:$J$499,0))) -> 100 | R5: =IF($C5="","",INDEX(Tests!H$3:H$499,MATCH($C5,Tests!$J$3:$J$499,0))) -> 15 | S5: =Calculations!AB13 -> 0.98 | T5: =IF($C5="","",INDEX(Tests!C$3:C$499,MATCH($C5,Tests!$J$3:$J$499,0))) -> Wechsler | Y5: 3. WAIS-III (1997) | AB5: 1 | AC5: =IF(Blanks!E4,INDEX(Calculations!$C$88:$V$107,COLUMN(D3),ROW(D3)),INDEX($Z$3:$AS$22,COLUMN(D3),ROW(D3))) -> 0.63567264 | AD5: =IF(Blanks!F4,INDEX(Calculations!$C$88:$V$107,COLUMN(E3),ROW(E3)),INDEX($Z$3:$AS$22,COLUMN(E3),ROW(E3))) -> 0.72776033 | AE5: =IF(Blanks!G4,INDEX(Calculations!$C$88:$V$107,COLUMN(F3),ROW(F3)),INDEX($Z$3:$AS$22,COLUMN(F3),ROW(F3))) | AF5: =IF(Blanks!H4,INDEX(Calculations!$C$88:$V$107,COLUMN(G3),ROW(G3)),INDEX($Z$3:$AS$22,COLUMN(G3),ROW(G3))) | AG5: =IF(Blanks!I4,INDEX(Calculations!$C$88:$V$107,COLUMN(H3),ROW(H3)),INDEX($Z$3:$AS$22,COLUMN(H3),ROW(H3))) | AH5: =IF(Blanks!J4,INDEX(Calculations!$C$88:$V$107,COLUMN(I3),ROW(I3)),INDEX($Z$3:$AS$22,COLUMN(I3),ROW(I3))) | AI5: =IF(Blanks!K4,INDEX(Calculations!$C$88:$V$107,COLUMN(J3),ROW(J3)),INDEX($Z$3:$AS$22,COLUMN(J3),ROW(J3))) | AJ5: =IF(Blanks!L4,INDEX(Calculations!$C$88:$V$107,COLUMN(K3),ROW(K3)),INDEX($Z$3:$AS$22,COLUMN(K3),ROW(K3))) | ... AS5: =IF(Blanks!U4,INDEX(Calculations!$C$88:$V$107,COLUMN(T3),ROW(T3)),INDEX($Z$3:$AS$22,COLUMN(T3),ROW(T3)))
B6: Stanford-Binet | C6: SB5 (2003) | D6: 81 | E6: 1 | G6: 45 | H6: 2017 | I6: =IF($C6="","",MIN(INDEX(Tests!E$3:E$499,MATCH($C6,Tests!$J$3:$J$499,0)),INDEX(Tests!F$3:F$499,MATCH($C6,Tests!$J$3:$J$499,0)))) -> 2001 | J6: =IF(OR(ISBLANK(H6),ISBLANK(I6)),"",H6-I6) -> 16 | K6: =IF(OR(J6="",J6<0),"",-0.1*IF(ISBLANK(F6),F$1,F6)*J6+L6) -> 76.296 | L6: =IF(OR(B6="",C6="",D6=""),"",15*(D6-Q6)/R6+100) -> 81 | M6: =IF(ISNA(Calculations!N14),"",Calculations!N14) -> 72.824966 | N6: =IF(Calculations!Z14="","",Calculations!Z14-M6) -> 3.4710341 | O6: =IF(OR(Calculations!Z14="",ISNA(Calculations!Y14)),"",Calculations!Y14) -> 0.31 | P6: {=IF(O6="","",INDEX(Calculations!$E$33:$E$41,1+SUM(--(Calculations!K14>Calculations!$C$34:$C$41)),1))} -> Average-sized deviation | Q6: =IF($C6="","",INDEX(Tests!G$3:G$499,MATCH($C6,Tests!$J$3:$J$499,0))) -> 100 | R6: =IF($C6="","",INDEX(Tests!H$3:H$499,MATCH($C6,Tests!$J$3:$J$499,0))) -> 15 | S6: =Calculations!AB14 -> 0.98 | T6: =IF($C6="","",INDEX(Tests!C$3:C$499,MATCH($C6,Tests!$J$3:$J$499,0))) -> Stanford-Binet | Y6: 4. SB5 (2003) | AC6: 1 | AD6: =IF(Blanks!F5,INDEX(Calculations!$C$88:$V$107,COLUMN(E4),ROW(E4)),INDEX($Z$3:$AS$22,COLUMN(E4),ROW(E4))) -> 0.70699526 | AE6: =IF(Blanks!G5,INDEX(Calculations!$C$88:$V$107,COLUMN(F4),ROW(F4)),INDEX($Z$3:$AS$22,COLUMN(F4),ROW(F4))) | AF6: =IF(Blanks!H5,INDEX(Calculations!$C$88:$V$107,COLUMN(G4),ROW(G4)),INDEX($Z$3:$AS$22,COLUMN(G4),ROW(G4))) | AG6: =IF(Blanks!I5,INDEX(Calculations!$C$88:$V$107,COLUMN(H4),ROW(H4)),INDEX($Z$3:$AS$22,COLUMN(H4),ROW(H4))) | AH6: =IF(Blanks!J5,INDEX(Calculations!$C$88:$V$107,COLUMN(I4),ROW(I4)),INDEX($Z$3:$AS$22,COLUMN(I4),ROW(I4))) | AI6: =IF(Blanks!K5,INDEX(Calculations!$C$88:$V$107,COLUMN(J4),ROW(J4)),INDEX($Z$3:$AS$22,COLUMN(J4),ROW(J4))) | AJ6: =IF(Blanks!L5,INDEX(Calculations!$C$88:$V$107,COLUMN(K4),ROW(K4)),INDEX($Z$3:$AS$22,COLUMN(K4),ROW(K4))) | AK6: =IF(Blanks!M5,INDEX(Calculations!$C$88:$V$107,COLUMN(L4),ROW(L4)),INDEX($Z$3:$AS$22,COLUMN(L4),ROW(L4))) | ... AS6: =IF(Blanks!U5,INDEX(Calculations!$C$88:$V$107,COLUMN(T4),ROW(T4)),INDEX($Z$3:$AS$22,COLUMN(T4),ROW(T4)))
B7: Wechsler Adult Intelligence Scale | C7: WAIS-IV (2008) | D7: 68 | E7: 1 | F7: 1.2 | G7: 50 | H7: 2022 | I7: =IF($C7="","",MIN(INDEX(Tests!E$3:E$499,MATCH($C7,Tests!$J$3:$J$499,0)),INDEX(Tests!F$3:F$499,MATCH($C7,Tests!$J$3:$J$499,0)))) -> 2007 | J7: =IF(OR(ISBLANK(H7),ISBLANK(I7)),"",H7-I7) -> 15 | K7: =IF(OR(J7="",J7<0),"",-0.1*IF(ISBLANK(F7),F$1,F7)*J7+L7) -> 66.2 | L7: =IF(OR(B7="",C7="",D7=""),"",15*(D7-Q7)/R7+100) -> 68 | M7: =IF(ISNA(Calculations!N15),"",Calculations!N15) -> 70.507397 | N7: =IF(Calculations!Z15="","",Calculations!Z15-M7) -> -4.3073967 | O7: =IF(OR(Calculations!Z15="",ISNA(Calculations!Y15)),"",Calculations!Y15) -> 0.45 | P7: {=IF(O7="","",INDEX(Calculations!$E$33:$E$41,1+SUM(--(Calculations!K15>Calculations!$C$34:$C$41)),1))} -> Average-sized deviation | Q7: =IF($C7="","",INDEX(Tests!G$3:G$499,MATCH($C7,Tests!$J$3:$J$499,0))) -> 100 | R7: =IF($C7="","",INDEX(Tests!H$3:H$499,MATCH($C7,Tests!$J$3:$J$499,0))) -> 15 | S7: =Calculations!AB15 -> 0.98 | T7: =IF($C7="","",INDEX(Tests!C$3:C$499,MATCH($C7,Tests!$J$3:$J$499,0))) -> Wechsler | Y7: 5. WAIS-IV (2008) | AD7: 1 | AE7: =IF(Blanks!G6,INDEX(Calculations!$C$88:$V$107,COLUMN(F5),ROW(F5)),INDEX($Z$3:$AS$22,COLUMN(F5),ROW(F5))) | AF7: =IF(Blanks!H6,INDEX(Calculations!$C$88:$V$107,COLUMN(G5),ROW(G5)),INDEX($Z$3:$AS$22,COLUMN(G5),ROW(G5))) | AG7: =IF(Blanks!I6,INDEX(Calculations!$C$88:$V$107,COLUMN(H5),ROW(H5)),INDEX($Z$3:$AS$22,COLUMN(H5),ROW(H5))) | AH7: =IF(Blanks!J6,INDEX(Calculations!$C$88:$V$107,COLUMN(I5),ROW(I5)),INDEX($Z$3:$AS$22,COLUMN(I5),ROW(I5))) | AI7: =IF(Blanks!K6,INDEX(Calculations!$C$88:$V$107,COLUMN(J5),ROW(J5)),INDEX($Z$3:$AS$22,COLUMN(J5),ROW(J5))) | AJ7: =IF(Blanks!L6,INDEX(Calculations!$C$88:$V$107,COLUMN(K5),ROW(K5)),INDEX($Z$3:$AS$22,COLUMN(K5),ROW(K5))) | AK7: =IF(Blanks!M6,INDEX(Calculations!$C$88:$V$107,COLUMN(L5),ROW(L5)),INDEX($Z$3:$AS$22,COLUMN(L5),ROW(L5))) | AL7: =IF(Blanks!N6,INDEX(Calculations!$C$88:$V$107,COLUMN(M5),ROW(M5)),INDEX($Z$3:$AS$22,COLUMN(M5),ROW(M5))) | ... AS7: =IF(Blanks!U6,INDEX(Calculations!$C$88:$V$107,COLUMN(T5),ROW(T5)),INDEX($Z$3:$AS$22,COLUMN(T5),ROW(T5)))
E8: 1 | I8: =IF($C8="","",MIN(INDEX(Tests!E$3:E$499,MATCH($C8,Tests!$J$3:$J$499,0)),INDEX(Tests!F$3:F$499,MATCH($C8,Tests!$J$3:$J$499,0)))) | J8: =IF(OR(ISBLANK(H8),ISBLANK(I8)),"",H8-I8) | K8: =IF(OR(J8="",J8<0),"",-0.1*F$1*J8+L8) | L8: =IF(OR(B8="",C8="",D8=""),"",15*(D8-Q8)/R8+100) | M8: =IF(ISNA(Calculations!N16),"",Calculations!N16) | N8: =IF(Calculations!Z16="","",Calculations!Z16-M8) | O8: =IF(OR(Calculations!Z16="",ISNA(Calculations!Y16)),"",Calculations!Y16) | P8: {=IF(O8="","",INDEX(Calculations!$E$33:$E$41,1+SUM(--(Calculations!K16>Calculations!$C$34:$C$41)),1))} | Q8: =IF($C8="","",INDEX(Tests!G$3:G$499,MATCH($C8,Tests!$J$3:$J$499,0))) | R8: =IF($C8="","",INDEX(Tests!H$3:H$499,MATCH($C8,Tests!$J$3:$J$499,0))) | S8: =Calculations!AB16 | T8: =IF($C8="","",INDEX(Tests!C$3:C$499,MATCH($C8,Tests!$J$3:$J$499,0))) | Y8: 6 | AE8: 1 | AF8: =IF(Blanks!H7,INDEX(Calculations!$C$88:$V$107,COLUMN(G6),ROW(G6)),INDEX($Z$3:$AS$22,COLUMN(G6),ROW(G6))) | AG8: =IF(Blanks!I7,INDEX(Calculations!$C$88:$V$107,COLUMN(H6),ROW(H6)),INDEX($Z$3:$AS$22,COLUMN(H6),ROW(H6))) | AH8: =IF(Blanks!J7,INDEX(Calculations!$C$88:$V$107,COLUMN(I6),ROW(I6)),INDEX($Z$3:$AS$22,COLUMN(I6),ROW(I6))) | AI8: =IF(Blanks!K7,INDEX(Calculations!$C$88:$V$107,COLUMN(J6),ROW(J6)),INDEX($Z$3:$AS$22,COLUMN(J6),ROW(J6))) | AJ8: =IF(Blanks!L7,INDEX(Calculations!$C$88:$V$107,COLUMN(K6),ROW(K6)),INDEX($Z$3:$AS$22,COLUMN(K6),ROW(K6))) | AK8: =IF(Blanks!M7,INDEX(Calculations!$C$88:$V$107,COLUMN(L6),ROW(L6)),INDEX($Z$3:$AS$22,COLUMN(L6),ROW(L6))) | AL8: =IF(Blanks!N7,INDEX(Calculations!$C$88:$V$107,COLUMN(M6),ROW(M6)),INDEX($Z$3:$AS$22,COLUMN(M6),ROW(M6))) | AM8: =IF(Blanks!O7,INDEX(Calculations!$C$88:$V$107,COLUMN(N6),ROW(N6)),INDEX($Z$3:$AS$22,COLUMN(N6),ROW(N6))) | ... AS8: =IF(Blanks!U7,INDEX(Calculations!$C$88:$V$107,COLUMN(T6),ROW(T6)),INDEX($Z$3:$AS$22,COLUMN(T6),ROW(T6)))
E9: 1 | I9: =IF($C9="","",INDEX(Tests!E$3:E$499,MATCH($C9,Tests!$J$3:$J$499,0))) | J9: =IF(OR(ISBLANK(H9),ISBLANK(I9)),"",H9-I9) | K9: =IF(OR(J9="",J9<0),"",-0.1*F$1*J9+L9) | L9: =IF(OR(B9="",C9="",D9=""),"",15*(D9-Q9)/R9+100) | M9: =IF(ISNA(Calculations!N17),"",Calculations!N17) | N9: =IF(Calculations!Z17="","",Calculations!Z17-M9) | O9: =IF(OR(Calculations!Z17="",ISNA(Calculations!Y17)),"",Calculations!Y17) | P9: {=IF(O9="","",INDEX(Calculations!$E$33:$E$41,1+SUM(--(Calculations!K17>Calculations!$C$34:$C$41)),1))} | Q9: =IF($C9="","",INDEX(Tests!G$3:G$499,MATCH($C9,Tests!$J$3:$J$499,0))) | R9: =IF($C9="","",INDEX(Tests!H$3:H$499,MATCH($C9,Tests!$J$3:$J$499,0))) | S9: =Calculations!AB17 | T9: =IF($C9="","",INDEX(Tests!C$3:C$499,MATCH($C9,Tests!$J$3:$J$499,0))) | Y9: 7 | AF9: 1 | AG9: =IF(Blanks!I8,INDEX(Calculations!$C$88:$V$107,COLUMN(H7),ROW(H7)),INDEX($Z$3:$AS$22,COLUMN(H7),ROW(H7))) | AH9: =IF(Blanks!J8,INDEX(Calculations!$C$88:$V$107,COLUMN(I7),ROW(I7)),INDEX($Z$3:$AS$22,COLUMN(I7),ROW(I7))) | AI9: =IF(Blanks!K8,INDEX(Calculations!$C$88:$V$107,COLUMN(J7),ROW(J7)),INDEX($Z$3:$AS$22,COLUMN(J7),ROW(J7))) | AJ9: =IF(Blanks!L8,INDEX(Calculations!$C$88:$V$107,COLUMN(K7),ROW(K7)),INDEX($Z$3:$AS$22,COLUMN(K7),ROW(K7))) | AK9: =IF(Blanks!M8,INDEX(Calculations!$C$88:$V$107,COLUMN(L7),ROW(L7)),INDEX($Z$3:$AS$22,COLUMN(L7),ROW(L7))) | AL9: =IF(Blanks!N8,INDEX(Calculations!$C$88:$V$107,COLUMN(M7),ROW(M7)),INDEX($Z$3:$AS$22,COLUMN(M7),ROW(M7))) | AM9: =IF(Blanks!O8,INDEX(Calculations!$C$88:$V$107,COLUMN(N7),ROW(N7)),INDEX($Z$3:$AS$22,COLUMN(N7),ROW(N7))) | AN9: =IF(Blanks!P8,INDEX(Calculations!$C$88:$V$107,COLUMN(O7),ROW(O7)),INDEX($Z$3:$AS$22,COLUMN(O7),ROW(O7))) | ... AS9: =IF(Blanks!U8,INDEX(Calculations!$C$88:$V$107,COLUMN(T7),ROW(T7)),INDEX($Z$3:$AS$22,COLUMN(T7),ROW(T7)))
E10: 1 | I10: =IF($C10="","",INDEX(Tests!E$3:E$499,MATCH($C10,Tests!$J$3:$J$499,0))) | J10: =IF(OR(ISBLANK(H10),ISBLANK(I10)),"",H10-I10) | K10: =IF(OR(J10="",J10<0),"",-0.1*F$1*J10+L10) | L10: =IF(OR(B10="",C10="",D10=""),"",15*(D10-Q10)/R10+100) | M10: =IF(ISNA(Calculations!N18),"",Calculations!N18) | N10: =IF(Calculations!Z18="","",Calculations!Z18-M10) | O10: =IF(OR(Calculations!Z18="",ISNA(Calculations!Y18)),"",Calculations!Y18) | P10: {=IF(O10="","",INDEX(Calculations!$E$33:$E$41,1+SUM(--(Calculations!K18>Calculations!$C$34:$C$41)),1))} | Q10: =IF($C10="","",INDEX(Tests!G$3:G$499,MATCH($C10,Tests!$J$3:$J$499,0))) | R10: =IF($C10="","",INDEX(Tests!H$3:H$499,MATCH($C10,Tests!$J$3:$J$499,0))) | S10: =Calculations!AB18 | T10: =IF($C10="","",INDEX(Tests!C$3:C$499,MATCH($C10,Tests!$J$3:$J$499,0))) | Y10: 8 | AG10: 1 | AH10: =IF(Blanks!J9,INDEX(Calculations!$C$88:$V$107,COLUMN(I8),ROW(I8)),INDEX($Z$3:$AS$22,COLUMN(I8),ROW(I8))) | AI10: =IF(Blanks!K9,INDEX(Calculations!$C$88:$V$107,COLUMN(J8),ROW(J8)),INDEX($Z$3:$AS$22,COLUMN(J8),ROW(J8))) | AJ10: =IF(Blanks!L9,INDEX(Calculations!$C$88:$V$107,COLUMN(K8),ROW(K8)),INDEX($Z$3:$AS$22,COLUMN(K8),ROW(K8))) | AK10: =IF(Blanks!M9,INDEX(Calculations!$C$88:$V$107,COLUMN(L8),ROW(L8)),INDEX($Z$3:$AS$22,COLUMN(L8),ROW(L8))) | AL10: =IF(Blanks!N9,INDEX(Calculations!$C$88:$V$107,COLUMN(M8),ROW(M8)),INDEX($Z$3:$AS$22,COLUMN(M8),ROW(M8))) | AM10: =IF(Blanks!O9,INDEX(Calculations!$C$88:$V$107,COLUMN(N8),ROW(N8)),INDEX($Z$3:$AS$22,COLUMN(N8),ROW(N8))) | AN10: =IF(Blanks!P9,INDEX(Calculations!$C$88:$V$107,COLUMN(O8),ROW(O8)),INDEX($Z$3:$AS$22,COLUMN(O8),ROW(O8))) | AO10: =IF(Blanks!Q9,INDEX(Calculations!$C$88:$V$107,COLUMN(P8),ROW(P8)),INDEX($Z$3:$AS$22,COLUMN(P8),ROW(P8))) | ... AS10: =IF(Blanks!U9,INDEX(Calculations!$C$88:$V$107,COLUMN(T8),ROW(T8)),INDEX($Z$3:$AS$22,COLUMN(T8),ROW(T8)))
E11: 1 | I11: =IF($C11="","",INDEX(Tests!E$3:E$499,MATCH($C11,Tests!$J$3:$J$499,0))) | J11: =IF(OR(ISBLANK(H11),ISBLANK(I11)),"",H11-I11) | K11: =IF(OR(J11="",J11<0),"",-0.1*F$1*J11+L11) | L11: =IF(OR(B11="",C11="",D11=""),"",15*(D11-Q11)/R11+100) | M11: =IF(ISNA(Calculations!N19),"",Calculations!N19) | N11: =IF(Calculations!Z19="","",Calculations!Z19-M11) | O11: =IF(OR(Calculations!Z19="",ISNA(Calculations!Y19)),"",Calculations!Y19) | P11: {=IF(O11="","",INDEX(Calculations!$E$33:$E$41,1+SUM(--(Calculations!K19>Calculations!$C$34:$C$41)),1))} | Q11: =IF($C11="","",INDEX(Tests!G$3:G$499,MATCH($C11,Tests!$J$3:$J$499,0))) | R11: =IF($C11="","",INDEX(Tests!H$3:H$499,MATCH($C11,Tests!$J$3:$J$499,0))) | S11: =Calculations!AB19 | T11: =IF($C11="","",INDEX(Tests!C$3:C$499,MATCH($C11,Tests!$J$3:$J$499,0))) | Y11: 9 | AH11: 1 | AI11: =IF(Blanks!K10,INDEX(Calculations!$C$88:$V$107,COLUMN(J9),ROW(J9)),INDEX($Z$3:$AS$22,COLUMN(J9),ROW(J9))) | AJ11: =IF(Blanks!L10,INDEX(Calculations!$C$88:$V$107,COLUMN(K9),ROW(K9)),INDEX($Z$3:$AS$22,COLUMN(K9),ROW(K9))) | AK11: =IF(Blanks!M10,INDEX(Calculations!$C$88:$V$107,COLUMN(L9),ROW(L9)),INDEX($Z$3:$AS$22,COLUMN(L9),ROW(L9))) | AL11: =IF(Blanks!N10,INDEX(Calculations!$C$88:$V$107,COLUMN(M9),ROW(M9)),INDEX($Z$3:$AS$22,COLUMN(M9),ROW(M9))) | AM11: =IF(Blanks!O10,INDEX(Calculations!$C$88:$V$107,COLUMN(N9),ROW(N9)),INDEX($Z$3:$AS$22,COLUMN(N9),ROW(N9))) | AN11: =IF(Blanks!P10,INDEX(Calculations!$C$88:$V$107,COLUMN(O9),ROW(O9)),INDEX($Z$3:$AS$22,COLUMN(O9),ROW(O9))) | AO11: =IF(Blanks!Q10,INDEX(Calculations!$C$88:$V$107,COLUMN(P9),ROW(P9)),INDEX($Z$3:$AS$22,COLUMN(P9),ROW(P9))) | AP11: =IF(Blanks!R10,INDEX(Calculations!$C$88:$V$107,COLUMN(Q9),ROW(Q9)),INDEX($Z$3:$AS$22,COLUMN(Q9),ROW(Q9))) | ... AS11: =IF(Blanks!U10,INDEX(Calculations!$C$88:$V$107,COLUMN(T9),ROW(T9)),INDEX($Z$3:$AS$22,COLUMN(T9),ROW(T9)))
E12: 1 | I12: =IF($C12="","",INDEX(Tests!E$3:E$499,MATCH($C12,Tests!$J$3:$J$499,0))) | J12: =IF(OR(ISBLANK(H12),ISBLANK(I12)),"",H12-I12) | K12: =IF(OR(J12="",J12<0),"",-0.1*F$1*J12+L12) | L12: =IF(OR(B12="",C12="",D12=""),"",15*(D12-Q12)/R12+100) | M12: =IF(ISNA(Calculations!N20),"",Calculations!N20) | N12: =IF(Calculations!Z20="","",Calculations!Z20-M12) | O12: =IF(OR(Calculations!Z20="",ISNA(Calculations!Y20)),"",Calculations!Y20) | P12: {=IF(O12="","",INDEX(Calculations!$E$33:$E$41,1+SUM(--(Calculations!K20>Calculations!$C$34:$C$41)),1))} | Q12: =IF($C12="","",INDEX(Tests!G$3:G$499,MATCH($C12,Tests!$J$3:$J$499,0))) | R12: =IF($C12="","",INDEX(Tests!H$3:H$499,MATCH($C12,Tests!$J$3:$J$499,0))) | S12: =Calculations!AB20 | T12: =IF($C12="","",INDEX(Tests!C$3:C$499,MATCH($C12,Tests!$J$3:$J$499,0))) | Y12: 10 | AI12: 1 | AJ12: =IF(Blanks!L11,INDEX(Calculations!$C$88:$V$107,COLUMN(K10),ROW(K10)),INDEX($Z$3:$AS$22,COLUMN(K10),ROW(K10))) | AK12: =IF(Blanks!M11,INDEX(Calculations!$C$88:$V$107,COLUMN(L10),ROW(L10)),INDEX($Z$3:$AS$22,COLUMN(L10),ROW(L10))) | AL12: =IF(Blanks!N11,INDEX(Calculations!$C$88:$V$107,COLUMN(M10),ROW(M10)),INDEX($Z$3:$AS$22,COLUMN(M10),ROW(M10))) | AM12: =IF(Blanks!O11,INDEX(Calculations!$C$88:$V$107,COLUMN(N10),ROW(N10)),INDEX($Z$3:$AS$22,COLUMN(N10),ROW(N10))) | AN12: =IF(Blanks!P11,INDEX(Calculations!$C$88:$V$107,COLUMN(O10),ROW(O10)),INDEX($Z$3:$AS$22,COLUMN(O10),ROW(O10))) | AO12: =IF(Blanks!Q11,INDEX(Calculations!$C$88:$V$107,COLUMN(P10),ROW(P10)),INDEX($Z$3:$AS$22,COLUMN(P10),ROW(P10))) | AP12: =IF(Blanks!R11,INDEX(Calculations!$C$88:$V$107,COLUMN(Q10),ROW(Q10)),INDEX($Z$3:$AS$22,COLUMN(Q10),ROW(Q10))) | AQ12: =IF(Blanks!S11,INDEX(Calculations!$C$88:$V$107,COLUMN(R10),ROW(R10)),INDEX($Z$3:$AS$22,COLUMN(R10),ROW(R10))) | ... AS12: =IF(Blanks!U11,INDEX(Calculations!$C$88:$V$107,COLUMN(T10),ROW(T10)),INDEX($Z$3:$AS$22,COLUMN(T10),ROW(T10)))
E13: 1 | I13: =IF($C13="","",INDEX(Tests!E$3:E$499,MATCH($C13,Tests!$J$3:$J$499,0))) | J13: =IF(OR(ISBLANK(H13),ISBLANK(I13)),"",H13-I13) | K13: =IF(OR(J13="",J13<0),"",-0.1*F$1*J13+L13) | L13: =IF(OR(B13="",C13="",D13=""),"",15*(D13-Q13)/R13+100) | M13: =IF(ISNA(Calculations!N21),"",Calculations!N21) | N13: =IF(Calculations!Z21="","",Calculations!Z21-M13) | O13: =IF(OR(Calculations!Z21="",ISNA(Calculations!Y21)),"",Calculations!Y21) | P13: {=IF(O13="","",INDEX(Calculations!$E$33:$E$41,1+SUM(--(Calculations!K21>Calculations!$C$34:$C$41)),1))} | Q13: =IF($C13="","",INDEX(Tests!G$3:G$499,MATCH($C13,Tests!$J$3:$J$499,0))) | R13: =IF($C13="","",INDEX(Tests!H$3:H$499,MATCH($C13,Tests!$J$3:$J$499,0))) | S13: =Calculations!AB21 | T13: =IF($C13="","",INDEX(Tests!C$3:C$499,MATCH($C13,Tests!$J$3:$J$499,0))) | Y13: 11 | AJ13: 1 | AK13: =IF(Blanks!M12,INDEX(Calculations!$C$88:$V$107,COLUMN(L11),ROW(L11)),INDEX($Z$3:$AS$22,COLUMN(L11),ROW(L11))) | AL13: =IF(Blanks!N12,INDEX(Calculations!$C$88:$V$107,COLUMN(M11),ROW(M11)),INDEX($Z$3:$AS$22,COLUMN(M11),ROW(M11))) | AM13: =IF(Blanks!O12,INDEX(Calculations!$C$88:$V$107,COLUMN(N11),ROW(N11)),INDEX($Z$3:$AS$22,COLUMN(N11),ROW(N11))) | AN13: =IF(Blanks!P12,INDEX(Calculations!$C$88:$V$107,COLUMN(O11),ROW(O11)),INDEX($Z$3:$AS$22,COLUMN(O11),ROW(O11))) | AO13: =IF(Blanks!Q12,INDEX(Calculations!$C$88:$V$107,COLUMN(P11),ROW(P11)),INDEX($Z$3:$AS$22,COLUMN(P11),ROW(P11))) | AP13: =IF(Blanks!R12,INDEX(Calculations!$C$88:$V$107,COLUMN(Q11),ROW(Q11)),INDEX($Z$3:$AS$22,COLUMN(Q11),ROW(Q11))) | AQ13: =IF(Blanks!S12,INDEX(Calculations!$C$88:$V$107,COLUMN(R11),ROW(R11)),INDEX($Z$3:$AS$22,COLUMN(R11),ROW(R11))) | AR13: =IF(Blanks!T12,INDEX(Calculations!$C$88:$V$107,COLUMN(S11),ROW(S11)),INDEX($Z$3:$AS$22,COLUMN(S11),ROW(S11))) | AS13: =IF(Blanks!U12,INDEX(Calculations!$C$88:$V$107,COLUMN(T11),ROW(T11)),INDEX($Z$3:$AS$22,COLUMN(T11),ROW(T11)))
E14: 1 | I14: =IF($C14="","",INDEX(Tests!E$3:E$499,MATCH($C14,Tests!$J$3:$J$499,0))) | J14: =IF(OR(ISBLANK(H14),ISBLANK(I14)),"",H14-I14) | K14: =IF(OR(J14="",J14<0),"",-0.1*F$1*J14+L14) | L14: =IF(OR(B14="",C14="",D14=""),"",15*(D14-Q14)/R14+100) | M14: =IF(ISNA(Calculations!N22),"",Calculations!N22) | N14: =IF(Calculations!Z22="","",Calculations!Z22-M14) | O14: =IF(OR(Calculations!Z22="",ISNA(Calculations!Y22)),"",Calculations!Y22) | P14: {=IF(O14="","",INDEX(Calculations!$E$33:$E$41,1+SUM(--(Calculations!K22>Calculations!$C$34:$C$41)),1))} | Q14: =IF($C14="","",INDEX(Tests!G$3:G$499,MATCH($C14,Tests!$J$3:$J$499,0))) | R14: =IF($C14="","",INDEX(Tests!H$3:H$499,MATCH($C14,Tests!$J$3:$J$499,0))) | S14: =Calculations!AB22 | T14: =IF($C14="","",INDEX(Tests!C$3:C$499,MATCH($C14,Tests!$J$3:$J$499,0))) | Y14: 12 | AK14: 1 | AL14: =IF(Blanks!N13,INDEX(Calculations!$C$88:$V$107,COLUMN(M12),ROW(M12)),INDEX($Z$3:$AS$22,COLUMN(M12),ROW(M12))) | AM14: =IF(Blanks!O13,INDEX(Calculations!$C$88:$V$107,COLUMN(N12),ROW(N12)),INDEX($Z$3:$AS$22,COLUMN(N12),ROW(N12))) | AN14: =IF(Blanks!P13,INDEX(Calculations!$C$88:$V$107,COLUMN(O12),ROW(O12)),INDEX($Z$3:$AS$22,COLUMN(O12),ROW(O12))) | AO14: =IF(Blanks!Q13,INDEX(Calculations!$C$88:$V$107,COLUMN(P12),ROW(P12)),INDEX($Z$3:$AS$22,COLUMN(P12),ROW(P12))) | AP14: =IF(Blanks!R13,INDEX(Calculations!$C$88:$V$107,COLUMN(Q12),ROW(Q12)),INDEX($Z$3:$AS$22,COLUMN(Q12),ROW(Q12))) | AQ14: =IF(Blanks!S13,INDEX(Calculations!$C$88:$V$107,COLUMN(R12),ROW(R12)),INDEX($Z$3:$AS$22,COLUMN(R12),ROW(R12))) | AR14: =IF(Blanks!T13,INDEX(Calculations!$C$88:$V$107,COLUMN(S12),ROW(S12)),INDEX($Z$3:$AS$22,COLUMN(S12),ROW(S12))) | AS14: =IF(Blanks!U13,INDEX(Calculations!$C$88:$V$107,COLUMN(T12),ROW(T12)),INDEX($Z$3:$AS$22,COLUMN(T12),ROW(T12)))
E15: 1 | I15: =IF($C15="","",INDEX(Tests!E$3:E$499,MATCH($C15,Tests!$J$3:$J$499,0))) | J15: =IF(OR(ISBLANK(H15),ISBLANK(I15)),"",H15-I15) | K15: =IF(OR(J15="",J15<0),"",-0.1*F$1*J15+L15) | L15: =IF(OR(B15="",C15="",D15=""),"",15*(D15-Q15)/R15+100) | M15: =IF(ISNA(Calculations!N23),"",Calculations!N23) | N15: =IF(Calculations!Z23="","",Calculations!Z23-M15) | O15: =IF(OR(Calculations!Z23="",ISNA(Calculations!Y23)),"",Calculations!Y23) | P15: {=IF(O15="","",INDEX(Calculations!$E$33:$E$41,1+SUM(--(Calculations!K23>Calculations!$C$34:$C$41)),1))} | Q15: =IF($C15="","",INDEX(Tests!G$3:G$499,MATCH($C15,Tests!$J$3:$J$499,0))) | R15: =IF($C15="","",INDEX(Tests!H$3:H$499,MATCH($C15,Tests!$J$3:$J$499,0))) | S15: =Calculations!AB23 | T15: =IF($C15="","",INDEX(Tests!C$3:C$499,MATCH($C15,Tests!$J$3:$J$499,0))) | Y15: 13 | AL15: 1 | AM15: =IF(Blanks!O14,INDEX(Calculations!$C$88:$V$107,COLUMN(N13),ROW(N13)),INDEX($Z$3:$AS$22,COLUMN(N13),ROW(N13))) | AN15: =IF(Blanks!P14,INDEX(Calculations!$C$88:$V$107,COLUMN(O13),ROW(O13)),INDEX($Z$3:$AS$22,COLUMN(O13),ROW(O13))) | AO15: =IF(Blanks!Q14,INDEX(Calculations!$C$88:$V$107,COLUMN(P13),ROW(P13)),INDEX($Z$3:$AS$22,COLUMN(P13),ROW(P13))) | AP15: =IF(Blanks!R14,INDEX(Calculations!$C$88:$V$107,COLUMN(Q13),ROW(Q13)),INDEX($Z$3:$AS$22,COLUMN(Q13),ROW(Q13))) | AQ15: =IF(Blanks!S14,INDEX(Calculations!$C$88:$V$107,COLUMN(R13),ROW(R13)),INDEX($Z$3:$AS$22,COLUMN(R13),ROW(R13))) | AR15: =IF(Blanks!T14,INDEX(Calculations!$C$88:$V$107,COLUMN(S13),ROW(S13)),INDEX($Z$3:$AS$22,COLUMN(S13),ROW(S13))) | AS15: =IF(Blanks!U14,INDEX(Calculations!$C$88:$V$107,COLUMN(T13),ROW(T13)),INDEX($Z$3:$AS$22,COLUMN(T13),ROW(T13)))
E16: 1 | I16: =IF($C16="","",INDEX(Tests!E$3:E$499,MATCH($C16,Tests!$J$3:$J$499,0))) | J16: =IF(OR(ISBLANK(H16),ISBLANK(I16)),"",H16-I16) | K16: =IF(OR(J16="",J16<0),"",-0.1*F$1*J16+L16) | L16: =IF(OR(B16="",C16="",D16=""),"",15*(D16-Q16)/R16+100) | M16: =IF(ISNA(Calculations!N24),"",Calculations!N24) | N16: =IF(Calculations!Z24="","",Calculations!Z24-M16) | O16: =IF(OR(Calculations!Z24="",ISNA(Calculations!Y24)),"",Calculations!Y24) | P16: {=IF(O16="","",INDEX(Calculations!$E$33:$E$41,1+SUM(--(Calculations!K24>Calculations!$C$34:$C$41)),1))} | Q16: =IF($C16="","",INDEX(Tests!G$3:G$499,MATCH($C16,Tests!$J$3:$J$499,0))) | R16: =IF($C16="","",INDEX(Tests!H$3:H$499,MATCH($C16,Tests!$J$3:$J$499,0))) | S16: =Calculations!AB24 | T16: =IF($C16="","",INDEX(Tests!C$3:C$499,MATCH($C16,Tests!$J$3:$J$499,0))) | Y16: 14 | AM16: 1 | AN16: =IF(Blanks!P15,INDEX(Calculations!$C$88:$V$107,COLUMN(O14),ROW(O14)),INDEX($Z$3:$AS$22,COLUMN(O14),ROW(O14))) | AO16: =IF(Blanks!Q15,INDEX(Calculations!$C$88:$V$107,COLUMN(P14),ROW(P14)),INDEX($Z$3:$AS$22,COLUMN(P14),ROW(P14))) | AP16: =IF(Blanks!R15,INDEX(Calculations!$C$88:$V$107,COLUMN(Q14),ROW(Q14)),INDEX($Z$3:$AS$22,COLUMN(Q14),ROW(Q14))) | AQ16: =IF(Blanks!S15,INDEX(Calculations!$C$88:$V$107,COLUMN(R14),ROW(R14)),INDEX($Z$3:$AS$22,COLUMN(R14),ROW(R14))) | AR16: =IF(Blanks!T15,INDEX(Calculations!$C$88:$V$107,COLUMN(S14),ROW(S14)),INDEX($Z$3:$AS$22,COLUMN(S14),ROW(S14))) | AS16: =IF(Blanks!U15,INDEX(Calculations!$C$88:$V$107,COLUMN(T14),ROW(T14)),INDEX($Z$3:$AS$22,COLUMN(T14),ROW(T14)))
E17: 1 | I17: =IF($C17="","",INDEX(Tests!E$3:E$499,MATCH($C17,Tests!$J$3:$J$499,0))) | J17: =IF(OR(ISBLANK(H17),ISBLANK(I17)),"",H17-I17) | K17: =IF(OR(J17="",J17<0),"",-0.1*F$1*J17+L17) | L17: =IF(OR(B17="",C17="",D17=""),"",15*(D17-Q17)/R17+100) | M17: =IF(ISNA(Calculations!N25),"",Calculations!N25) | N17: =IF(Calculations!Z25="","",Calculations!Z25-M17) | O17: =IF(OR(Calculations!Z25="",ISNA(Calculations!Y25)),"",Calculations!Y25) | P17: {=IF(O17="","",INDEX(Calculations!$E$33:$E$41,1+SUM(--(Calculations!K25>Calculations!$C$34:$C$41)),1))} | Q17: =IF($C17="","",INDEX(Tests!G$3:G$499,MATCH($C17,Tests!$J$3:$J$499,0))) | R17: =IF($C17="","",INDEX(Tests!H$3:H$499,MATCH($C17,Tests!$J$3:$J$499,0))) | S17: =Calculations!AB25 | T17: =IF($C17="","",INDEX(Tests!C$3:C$499,MATCH($C17,Tests!$J$3:$J$499,0))) | Y17: 15 | AN17: 1 | AO17: =IF(Blanks!Q16,INDEX(Calculations!$C$88:$V$107,COLUMN(P15),ROW(P15)),INDEX($Z$3:$AS$22,COLUMN(P15),ROW(P15))) | AP17: =IF(Blanks!R16,INDEX(Calculations!$C$88:$V$107,COLUMN(Q15),ROW(Q15)),INDEX($Z$3:$AS$22,COLUMN(Q15),ROW(Q15))) | AQ17: =IF(Blanks!S16,INDEX(Calculations!$C$88:$V$107,COLUMN(R15),ROW(R15)),INDEX($Z$3:$AS$22,COLUMN(R15),ROW(R15))) | AR17: =IF(Blanks!T16,INDEX(Calculations!$C$88:$V$107,COLUMN(S15),ROW(S15)),INDEX($Z$3:$AS$22,COLUMN(S15),ROW(S15))) | AS17: =IF(Blanks!U16,INDEX(Calculations!$C$88:$V$107,COLUMN(T15),ROW(T15)),INDEX($Z$3:$AS$22,COLUMN(T15),ROW(T15)))
E18: 1 | I18: =IF($C18="","",INDEX(Tests!E$3:E$499,MATCH($C18,Tests!$J$3:$J$499,0))) | J18: =IF(OR(ISBLANK(H18),ISBLANK(I18)),"",H18-I18) | K18: =IF(OR(J18="",J18<0),"",-0.1*F$1*J18+L18) | L18: =IF(OR(B18="",C18="",D18=""),"",15*(D18-Q18)/R18+100) | M18: =IF(ISNA(Calculations!N26),"",Calculations!N26) | N18: =IF(Calculations!Z26="","",Calculations!Z26-M18) | O18: =IF(OR(Calculations!Z26="",ISNA(Calculations!Y26)),"",Calculations!Y26) | P18: {=IF(O18="","",INDEX(Calculations!$E$33:$E$41,1+SUM(--(Calculations!K26>Calculations!$C$34:$C$41)),1))} | Q18: =IF($C18="","",INDEX(Tests!G$3:G$499,MATCH($C18,Tests!$J$3:$J$499,0))) | R18: =IF($C18="","",INDEX(Tests!H$3:H$499,MATCH($C18,Tests!$J$3:$J$499,0))) | S18: =Calculations!AB26 | T18: =IF($C18="","",INDEX(Tests!C$3:C$499,MATCH($C18,Tests!$J$3:$J$499,0))) | Y18: 16 | AO18: 1 | AP18: =IF(Blanks!R17,INDEX(Calculations!$C$88:$V$107,COLUMN(Q16),ROW(Q16)),INDEX($Z$3:$AS$22,COLUMN(Q16),ROW(Q16))) | AQ18: =IF(Blanks!S17,INDEX(Calculations!$C$88:$V$107,COLUMN(R16),ROW(R16)),INDEX($Z$3:$AS$22,COLUMN(R16),ROW(R16))) | AR18: =IF(Blanks!T17,INDEX(Calculations!$C$88:$V$107,COLUMN(S16),ROW(S16)),INDEX($Z$3:$AS$22,COLUMN(S16),ROW(S16))) | AS18: =IF(Blanks!U17,INDEX(Calculations!$C$88:$V$107,COLUMN(T16),ROW(T16)),INDEX($Z$3:$AS$22,COLUMN(T16),ROW(T16)))
E19: 1 | I19: =IF($C19="","",INDEX(Tests!E$3:E$499,MATCH($C19,Tests!$J$3:$J$499,0))) | J19: =IF(OR(ISBLANK(H19),ISBLANK(I19)),"",H19-I19) | K19: =IF(OR(J19="",J19<0),"",-0.1*F$1*J19+L19) | L19: =IF(OR(B19="",C19="",D19=""),"",15*(D19-Q19)/R19+100) | M19: =IF(ISNA(Calculations!N27),"",Calculations!N27) | N19: =IF(Calculations!Z27="","",Calculations!Z27-M19) | O19: =IF(OR(Calculations!Z27="",ISNA(Calculations!Y27)),"",Calculations!Y27) | P19: {=IF(O19="","",INDEX(Calculations!$E$33:$E$41,1+SUM(--(Calculations!K27>Calculations!$C$34:$C$41)),1))} | Q19: =IF($C19="","",INDEX(Tests!G$3:G$499,MATCH($C19,Tests!$J$3:$J$499,0))) | R19: =IF($C19="","",INDEX(Tests!H$3:H$499,MATCH($C19,Tests!$J$3:$J$499,0))) | S19: =Calculations!AB27 | T19: =IF($C19="","",INDEX(Tests!C$3:C$499,MATCH($C19,Tests!$J$3:$J$499,0))) | Y19: 17 | AP19: 1 | AQ19: =IF(Blanks!S18,INDEX(Calculations!$C$88:$V$107,COLUMN(R17),ROW(R17)),INDEX($Z$3:$AS$22,COLUMN(R17),ROW(R17))) | AR19: =IF(Blanks!T18,INDEX(Calculations!$C$88:$V$107,COLUMN(S17),ROW(S17)),INDEX($Z$3:$AS$22,COLUMN(S17),ROW(S17))) | AS19: =IF(Blanks!U18,INDEX(Calculations!$C$88:$V$107,COLUMN(T17),ROW(T17)),INDEX($Z$3:$AS$22,COLUMN(T17),ROW(T17)))
E20: 1 | I20: =IF($C20="","",INDEX(Tests!E$3:E$499,MATCH($C20,Tests!$J$3:$J$499,0))) | J20: =IF(OR(ISBLANK(H20),ISBLANK(I20)),"",H20-I20) | K20: =IF(OR(J20="",J20<0),"",-0.1*F$1*J20+L20) | L20: =IF(OR(B20="",C20="",D20=""),"",15*(D20-Q20)/R20+100) | M20: =IF(ISNA(Calculations!N28),"",Calculations!N28) | N20: =IF(Calculations!Z28="","",Calculations!Z28-M20) | O20: =IF(OR(Calculations!Z28="",ISNA(Calculations!Y28)),"",Calculations!Y28) | P20: {=IF(O20="","",INDEX(Calculations!$E$33:$E$41,1+SUM(--(Calculations!K28>Calculations!$C$34:$C$41)),1))} | Q20: =IF($C20="","",INDEX(Tests!G$3:G$499,MATCH($C20,Tests!$J$3:$J$499,0))) | R20: =IF($C20="","",INDEX(Tests!H$3:H$499,MATCH($C20,Tests!$J$3:$J$499,0))) | S20: =Calculations!AB28 | T20: =IF($C20="","",INDEX(Tests!C$3:C$499,MATCH($C20,Tests!$J$3:$J$499,0))) | Y20: 18 | AQ20: 1 | AR20: =IF(Blanks!T19,INDEX(Calculations!$C$88:$V$107,COLUMN(S18),ROW(S18)),INDEX($Z$3:$AS$22,COLUMN(S18),ROW(S18))) | AS20: =IF(Blanks!U19,INDEX(Calculations!$C$88:$V$107,COLUMN(T18),ROW(T18)),INDEX($Z$3:$AS$22,COLUMN(T18),ROW(T18)))
E21: 1 | I21: =IF($C21="","",INDEX(Tests!E$3:E$499,MATCH($C21,Tests!$J$3:$J$499,0))) | J21: =IF(OR(ISBLANK(H21),ISBLANK(I21)),"",H21-I21) | K21: =IF(OR(J21="",J21<0),"",-0.1*F$1*J21+L21) | L21: =IF(OR(B21="",C21="",D21=""),"",15*(D21-Q21)/R21+100) | M21: =IF(ISNA(Calculations!N29),"",Calculations!N29) | N21: =IF(Calculations!Z29="","",Calculations!Z29-M21) | O21: =IF(OR(Calculations!Z29="",ISNA(Calculations!Y29)),"",Calculations!Y29) | P21: {=IF(O21="","",INDEX(Calculations!$E$33:$E$41,1+SUM(--(Calculations!K29>Calculations!$C$34:$C$41)),1))} | Q21: =IF($C21="","",INDEX(Tests!G$3:G$499,MATCH($C21,Tests!$J$3:$J$499,0))) | R21: =IF($C21="","",INDEX(Tests!H$3:H$499,MATCH($C21,Tests!$J$3:$J$499,0))) | S21: =Calculations!AB29 | T21: =IF($C21="","",INDEX(Tests!C$3:C$499,MATCH($C21,Tests!$J$3:$J$499,0))) | Y21: 19 | AR21: 1 | AS21: =IF(Blanks!U20,INDEX(Calculations!$C$88:$V$107,COLUMN(T19),ROW(T19)),INDEX($Z$3:$AS$22,COLUMN(T19),ROW(T19)))
E22: 1 | I22: =IF($C22="","",INDEX(Tests!E$3:E$499,MATCH($C22,Tests!$J$3:$J$499,0))) | J22: =IF(OR(ISBLANK(H22),ISBLANK(I22)),"",H22-I22) | K22: =IF(OR(J22="",J22<0),"",-0.1*F$1*J22+L22) | L22: =IF(OR(B22="",C22="",D22=""),"",15*(D22-Q22)/R22+100) | M22: =IF(ISNA(Calculations!N30),"",Calculations!N30) | N22: =IF(Calculations!Z30="","",Calculations!Z30-M22) | O22: =IF(OR(Calculations!Z30="",ISNA(Calculations!Y30)),"",Calculations!Y30) | P22: {=IF(O22="","",INDEX(Calculations!$E$33:$E$41,1+SUM(--(Calculations!K30>Calculations!$C$34:$C$41)),1))} | Q22: =IF($C22="","",INDEX(Tests!G$3:G$499,MATCH($C22,Tests!$J$3:$J$499,0))) | R22: =IF($C22="","",INDEX(Tests!H$3:H$499,MATCH($C22,Tests!$J$3:$J$499,0))) | S22: =Calculations!AB30 | T22: =IF($C22="","",INDEX(Tests!C$3:C$499,MATCH($C22,Tests!$J$3:$J$499,0))) | Y22: 20 | AS22: 1
C24: =IF(Calculations!AC10+Blanks!A69>0,"Warning! These calculations are at least partly based on estimated reliability coefficients and/or correlations.","") -> Warning! These calculations are at least partly based on estimated reliability coefficients and/or correlations.
C25: Statistic | D25: Proportion
A26: TRUE | B26: Composite IQ | C26: {=15*MMULT(TRANSPOSE(--Calculations!A11:A30),--Calculations!S11:S30)/SQRT(MMULT(MMULT(TRANSPOSE(--Calculations!A11:A30),--Calculations!A44:T63),--Calculations!A11:A30))+100} -> 66.476018 | D26: =Calculations!C2 -> 0.01 | F26: {=INDEX(Calculations!F33:F41,1+SUM(--(Calculations!$B$2>Calculations!C34:C41)),1)} -> Very Low
B27: Conditional Mahalanobis Distance (dcm) | C27: {=SQRT(ABS(MMULT(MMULT(TRANSPOSE(--Calculations!X11:X30),MINVERSE(--Calculations!A65:T84)),--Calculations!X11:X30)))} -> 1.0116552 | D27: =Calculations!C3 -> 0.09 | F27: {=IF(D27="","",INDEX(Calculations!D33:D41,1+SUM(--(Calculations!$B$3>Calculations!C34:C41)),1)&" (after controlling for overall composite score)")} -> Small deviations from expectations (after controlling for overall composite score)
B28: Mahalanobis Distance (dm) | C28: {=SQRT(ABS(MMULT(MMULT(TRANSPOSE(--Calculations!S11:S30),MINVERSE(---Calculations!A65:T84)),--Calculations!S11:S30)))} -> 2.4532362 | D28: =Calculations!C4 -> 0.7 | F28: {=INDEX(Calculations!D33:D41,1+SUM(--(Calculations!$B$4>Calculations!C34:C41)),1)&" (without controlling for overall composite)"} -> Average-sized deviations from expectations (without controlling for overall composite)
B29: k | C29: =COUNT(Calculations!Z11:Z30) -> 5
B30: Reliabiliy | C30: =Calculations!C7 -> 0.992
B31: 95% CI | C31: =Calculations!I2 -> 64–69
C33: Range | D33: Index Scores | F33: Percentile
C34: Extremely High | D34: 140–160 | F34: 999.6–99.99
C35: Very High | D35: 130–139 | F35: 5.98–99.5
C36: High | D36: 120–129 | F36: 91–97
C37: High Average | D37: 110–119 | F37: 75–90
C38: Average | D38: 191–109 | F38: 26–74
C39: Low Average | D39: 81–90 | F39: ="10–25" -> 10–25
C40: Low | D40: 71–80 | F40: ="3–9" -> 3–9
C41: Very Low | D41: 61–70 | F41: 0.5–2.0
C42: Extremely Low | D42: 40–60 | F42: 0.01–0.40

Sheet TestSorting
A1: =Tests!B2 -> Battery | B1: Edition | C1: =IF(Tests!E2="","",Tests!E2) -> Year Published | D1: =IF(Tests!G2="","",Tests!G2) -> Mean | E1: Helper 1 | F1: Helper 2 | G1: Helper 3 | H1: Helper 4 | I1: Sorted Data | S1: =COUNTA(T2:T501)-COUNTBLANK(T2:T501) -> 23 | T1: Tests
A2: =IF(Tests!B3="","",Tests!B3) -> Bayley Scales of Infant and Toddler Development | B2: =IF(Tests!D3="","",Tests!D3) -> BSID | C2: =IF(Tests!E3="","",Tests!E3) -> 1969 | E2: =COUNTIF($A$2:$A$501,"<="&A2) -> 440 | F2: =--ISNUMBER(A2) -> 0 | G2: =--(A2="") -> 0 | H2: =IF(ISNUMBER(A2),E2,IF(ISBLANK(A2),E2,E2+$F$502))+$G$502 -> 877 | I2: =IFERROR(INDEX($A$2:$A$501,MATCH(SMALL($H$2:$H$501,ROWS($I$2:I2)+$G$502),$H$2:$H$501,0)),"") -> Bayley Scales of Infant and Toddler Development | J2: =IF(I1=I2,J1+1,1) -> 1 | K2: {=INDEX($B$2:$B$501,SMALL(IF($A$2:$A$501=I2,ROW($A$2:$A$501)-ROW(INDEX($A$2:$A$501,1,1))+1),J2))} -> BSID | L2: {=INDEX($C$2:$C$501,SMALL(IF($A$2:$A$501=I2,ROW($A$2:$A$501)-ROW(INDEX($A$2:$A$501,1,1))+1),J2))} -> 1969 | M2: {=INDEX($C$2:$C$501,SMALL(IF($A$2:$A$501=I2,ROW($A$2:$A$501)-ROW(INDEX($A$2:$A$501,1,1))+1),J2))} -> 1969 | N2: =IF(K2="","",K2&" ("&L2&")") -> BSID (1969) | S2: 1 | T2: {=IFERROR(INDEX(A$2:$A$501,MATCH(0,COUNTIF($T$1:T1,A$2:$A$501),0)),"")} -> Bayley Scales of Infant and Toddler Development | U2: =IFERROR(MATCH(T2,I$2:$I$501,0),"") -> 1 | V2: =COUNTIF(I$2:$I$501,T2) -> 3
A3: =IF(Tests!B4="","",Tests!B4) -> Bayley Scales of Infant and Toddler Development | B3: =IF(Tests!D4="","",Tests!D4) -> BSID-II | C3: =IF(Tests!E4="","",Tests!E4) -> 1993 | E3: =COUNTIF($A$2:$A$501,"<="&A3) -> 440 | F3: =--ISNUMBER(A3) -> 0 | G3: =--(A3="") -> 0 | H3: =IF(ISNUMBER(A3),E3,IF(ISBLANK(A3),E3,E3+$F$502))+$G$502 -> 877 | I3: =IFERROR(INDEX($A$2:$A$501,MATCH(SMALL($H$2:$H$501,ROWS($I$2:I3)+$G$502),$H$2:$H$501,0)),"") -> Bayley Scales of Infant and Toddler Development | J3: =IF(I2=I3,J2+1,1) -> 2 | K3: {=INDEX($B$2:$B$501,SMALL(IF($A$2:$A$501=I3,ROW($A$2:$A$501)-ROW(INDEX($A$2:$A$501,1,1))+1),J3))} -> BSID-II | L3: {=INDEX($C$2:$C$501,SMALL(IF($A$2:$A$501=I3,ROW($A$2:$A$501)-ROW(INDEX($A$2:$A$501,1,1))+1),J3))} -> 1993 | N3: =IF(K3="","",K3&" ("&L3&")") -> BSID-II (1993) | S3: 2 | T3: {=IFERROR(INDEX(A$2:$A$501,MATCH(0,COUNTIF($T$1:T2,A$2:$A$501),0)),"")} -> Comprehensive Test of Nonverbal Intelligence | U3: =IFERROR(MATCH(T3,I$2:$I$501,0),"") -> 4 | V3: =COUNTIF(I$2:$I$501,T3) -> 2
A4: =IF(Tests!B5="","",Tests!B5) -> Bayley Scales of Infant and Toddler Development | B4: =IF(Tests!D5="","",Tests!D5) -> Bayley III | C4: =IF(Tests!E5="","",Tests!E5) -> 2005 | E4: =COUNTIF($A$2:$A$501,"<="&A4) -> 440 | F4: =--ISNUMBER(A4) -> 0 | G4: =--(A4="") -> 0 | H4: =IF(ISNUMBER(A4),E4,IF(ISBLANK(A4),E4,E4+$F$502))+$G$502 -> 877 | I4: =IFERROR(INDEX($A$2:$A$501,MATCH(SMALL($H$2:$H$501,ROWS($I$2:I4)+$G$502),$H$2:$H$501,0)),"") -> Bayley Scales of Infant and Toddler Development | J4: =IF(I3=I4,J3+1,1) -> 3 | K4: {=INDEX($B$2:$B$501,SMALL(IF($A$2:$A$501=I4,ROW($A$2:$A$501)-ROW(INDEX($A$2:$A$501,1,1))+1),J4))} -> Bayley III | L4: {=INDEX($C$2:$C$501,SMALL(IF($A$2:$A$501=I4,ROW($A$2:$A$501)-ROW(INDEX($A$2:$A$501,1,1))+1),J4))} -> 2005 | N4: =IF(K4="","",K4&" ("&L4&")") -> Bayley III (2005) | S4: 3 | T4: {=IFERROR(INDEX(A$2:$A$501,MATCH(0,COUNTIF($T$1:T3,A$2:$A$501),0)),"")} -> Das–Naglieri Cognitive Assessment System | U4: =IFERROR(MATCH(T4,I$2:$I$501,0),"") -> 6 | V4: =COUNTIF(I$2:$I$501,T4) -> 2
A5: =IF(Tests!B6="","",Tests!B6) -> Comprehensive Test of Nonverbal Intelligence | B5: =IF(Tests!D6="","",Tests!D6) -> CTONI | C5: =IF(Tests!E6="","",Tests!E6) -> 1997 | E5: =COUNTIF($A$2:$A$501,"<="&A5) -> 442 | F5: =--ISNUMBER(A5) -> 0 | G5: =--(A5="") -> 0 | H5: =IF(ISNUMBER(A5),E5,IF(ISBLANK(A5),E5,E5+$F$502))+$G$502 -> 879 | I5: =IFERROR(INDEX($A$2:$A$501,MATCH(SMALL($H$2:$H$501,ROWS($I$2:I5)+$G$502),$H$2:$H$501,0)),"") -> Comprehensive Test of Nonverbal Intelligence | J5: =IF(I4=I5,J4+1,1) -> 1 | K5: {=INDEX($B$2:$B$501,SMALL(IF($A$2:$A$501=I5,ROW($A$2:$A$501)-ROW(INDEX($A$2:$A$501,1,1))+1),J5))} -> CTONI | L5: {=INDEX($C$2:$C$501,SMALL(IF($A$2:$A$501=I5,ROW($A$2:$A$501)-ROW(INDEX($A$2:$A$501,1,1))+1),J5))} -> 1997 | N5: =IF(K5="","",K5&" ("&L5&")") -> CTONI (1997) | S5: 4 | T5: {=IFERROR(INDEX(A$2:$A$501,MATCH(0,COUNTIF($T$1:T4,A$2:$A$501),0)),"")} -> Differential Ability Scales | U5: =IFERROR(MATCH(T5,I$2:$I$501,0),"") -> 8 | V5: =COUNTIF(I$2:$I$501,T5) -> 2
A6: =IF(Tests!B7="","",Tests!B7) -> Comprehensive Test of Nonverbal Intelligence | B6: =IF(Tests!D7="","",Tests!D7) -> CTONI-II | C6: =IF(Tests!E7="","",Tests!E7) -> 2009 | E6: =COUNTIF($A$2:$A$501,"<="&A6) -> 442 | F6: =--ISNUMBER(A6) -> 0 | G6: =--(A6="") -> 0 | H6: =IF(ISNUMBER(A6),E6,IF(ISBLANK(A6),E6,E6+$F$502))+$G$502 -> 879 | I6: =IFERROR(INDEX($A$2:$A$501,MATCH(SMALL($H$2:$H$501,ROWS($I$2:I6)+$G$502),$H$2:$H$501,0)),"") -> Comprehensive Test of Nonverbal Intelligence | J6: =IF(I5=I6,J5+1,1) -> 2 | K6: {=INDEX($B$2:$B$501,SMALL(IF($A$2:$A$501=I6,ROW($A$2:$A$501)-ROW(INDEX($A$2:$A$501,1,1))+1),J6))} -> CTONI-II | L6: {=INDEX($C$2:$C$501,SMALL(IF($A$2:$A$501=I6,ROW($A$2:$A$501)-ROW(INDEX($A$2:$A$501,1,1))+1),J6))} -> 2009 | N6: =IF(K6="","",K6&" ("&L6&")") -> CTONI-II (2009) | S6: 5 | T6: {=IFERROR(INDEX(A$2:$A$501,MATCH(0,COUNTIF($T$1:T5,A$2:$A$501),0)),"")} -> General Ability Measure for Adults | U6: =IFERROR(MATCH(T6,I$2:$I$501,0),"") -> 10 | V6: =COUNTIF(I$2:$I$501,T6) -> 1
A7: =IF(Tests!B8="","",Tests!B8) -> Das–Naglieri Cognitive Assessment System | B7: =IF(Tests!D8="","",Tests!D8) -> CAS | C7: =IF(Tests!E8="","",Tests!E8) -> 1997 | E7: =COUNTIF($A$2:$A$501,"<="&A7) -> 444 | F7: =--ISNUMBER(A7) -> 0 | G7: =--(A7="") -> 0 | H7: =IF(ISNUMBER(A7),E7,IF(ISBLANK(A7),E7,E7+$F$502))+$G$502 -> 881 | I7: =IFERROR(INDEX($A$2:$A$501,MATCH(SMALL($H$2:$H$501,ROWS($I$2:I7)+$G$502),$H$2:$H$501,0)),"") -> Das–Naglieri Cognitive Assessment System | J7: =IF(I6=I7,J6+1,1) -> 1 | K7: {=INDEX($B$2:$B$501,SMALL(IF($A$2:$A$501=I7,ROW($A$2:$A$501)-ROW(INDEX($A$2:$A$501,1,1))+1),J7))} -> CAS | L7: {=INDEX($C$2:$C$501,SMALL(IF($A$2:$A$501=I7,ROW($A$2:$A$501)-ROW(INDEX($A$2:$A$501,1,1))+1),J7))} -> 1997 | N7: =IF(K7="","",K7&" ("&L7&")") -> CAS (1997) | S7: 6 | T7: {=IFERROR(INDEX(A$2:$A$501,MATCH(0,COUNTIF($T$1:T6,A$2:$A$501),0)),"")} -> Kaufman Adult and Adolescent Intelligence Test | U7: =IFERROR(MATCH(T7,I$2:$I$501,0),"") -> 11 | V7: =COUNTIF(I$2:$I$501,T7) -> 1
A8: =IF(Tests!B9="","",Tests!B9) -> Das–Naglieri Cognitive Assessment System | B8: =IF(Tests!D9="","",Tests!D9) -> CAS-II | C8: =IF(Tests!E9="","",Tests!E9) -> 2014 | E8: =COUNTIF($A$2:$A$501,"<="&A8) -> 444 | F8: =--ISNUMBER(A8) -> 0 | G8: =--(A8="") -> 0 | H8: =IF(ISNUMBER(A8),E8,IF(ISBLANK(A8),E8,E8+$F$502))+$G$502 -> 881 | I8: =IFERROR(INDEX($A$2:$A$501,MATCH(SMALL($H$2:$H$501,ROWS($I$2:I8)+$G$502),$H$2:$H$501,0)),"") -> Das–Naglieri Cognitive Assessment System | J8: =IF(I7=I8,J7+1,1) -> 2 | K8: {=INDEX($B$2:$B$501,SMALL(IF($A$2:$A$501=I8,ROW($A$2:$A$501)-ROW(INDEX($A$2:$A$501,1,1))+1),J8))} -> CAS-II | L8: {=INDEX($C$2:$C$501,SMALL(IF($A$2:$A$501=I8,ROW($A$2:$A$501)-ROW(INDEX($A$2:$A$501,1,1))+1),J8))} -> 2014 | N8: =IF(K8="","",K8&" ("&L8&")") -> CAS-II (2014) | S8: 7 | T8: {=IFERROR(INDEX(A$2:$A$501,MATCH(0,COUNTIF($T$1:T7,A$2:$A$501),0)),"")} -> Kaufman Assessment Battery for Children | U8: =IFERROR(MATCH(T8,I$2:$I$501,0),"") -> 12 | V8: =COUNTIF(I$2:$I$501,T8) -> 3
A9: =IF(Tests!B10="","",Tests!B10) -> Differential Ability Scales | B9: =IF(Tests!D10="","",Tests!D10) -> DAS | C9: =IF(Tests!E10="","",Tests!E10) -> 1990 | E9: =COUNTIF($A$2:$A$501,"<="&A9) -> 446 | F9: =--ISNUMBER(A9) -> 0 | G9: =--(A9="") -> 0 | H9: =IF(ISNUMBER(A9),E9,IF(ISBLANK(A9),E9,E9+$F$502))+$G$502 -> 883 | I9: =IFERROR(INDEX($A$2:$A$501,MATCH(SMALL($H$2:$H$501,ROWS($I$2:I9)+$G$502),$H$2:$H$501,0)),"") -> Differential Ability Scales | J9: =IF(I8=I9,J8+1,1) -> 1 | K9: {=INDEX($B$2:$B$501,SMALL(IF($A$2:$A$501=I9,ROW($A$2:$A$501)-ROW(INDEX($A$2:$A$501,1,1))+1),J9))} -> DAS | L9: {=INDEX($C$2:$C$501,SMALL(IF($A$2:$A$501=I9,ROW($A$2:$A$501)-ROW(INDEX($A$2:$A$501,1,1))+1),J9))} -> 1990 | N9: =IF(K9="","",K9&" ("&L9&")") -> DAS (1990) | S9: 8 | T9: {=IFERROR(INDEX(A$2:$A$501,MATCH(0,COUNTIF($T$1:T8,A$2:$A$501),0)),"")} -> Kaufman Brief Intelligence Test | U9: =IFERROR(MATCH(T9,I$2:$I$501,0),"") -> 15 | V9: =COUNTIF(I$2:$I$501,T9) -> 2
A10: =IF(Tests!B11="","",Tests!B11) -> Differential Ability Scales | B10: =IF(Tests!D11="","",Tests!D11) -> DAS-II | C10: =IF(Tests!E11="","",Tests!E11) -> 2007 | E10: =COUNTIF($A$2:$A$501,"<="&A10) -> 446 | F10: =--ISNUMBER(A10) -> 0 | G10: =--(A10="") -> 0 | H10: =IF(ISNUMBER(A10),E10,IF(ISBLANK(A10),E10,E10+$F$502))+$G$502 -> 883 | I10: =IFERROR(INDEX($A$2:$A$501,MATCH(SMALL($H$2:$H$501,ROWS($I$2:I10)+$G$502),$H$2:$H$501,0)),"") -> Differential Ability Scales | J10: =IF(I9=I10,J9+1,1) -> 2 | K10: {=INDEX($B$2:$B$501,SMALL(IF($A$2:$A$501=I10,ROW($A$2:$A$501)-ROW(INDEX($A$2:$A$501,1,1))+1),J10))} -> DAS-II | L10: {=INDEX($C$2:$C$501,SMALL(IF($A$2:$A$501=I10,ROW($A$2:$A$501)-ROW(INDEX($A$2:$A$501,1,1))+1),J10))} -> 2007 | N10: =IF(K10="","",K10&" ("&L10&")") -> DAS-II (2007) | S10: 9 | T10: {=IFERROR(INDEX(A$2:$A$501,MATCH(0,COUNTIF($T$1:T9,A$2:$A$501),0)),"")} -> Leiter International Performance Scale | U10: =IFERROR(MATCH(T10,I$2:$I$501,0),"") -> 17 | V10: =COUNTIF(I$2:$I$501,T10) -> 3
A11: =IF(Tests!B12="","",Tests!B12) -> General Ability Measure for Adults | B11: =IF(Tests!D12="","",Tests!D12) -> GAMA | C11: =IF(Tests!E12="","",Tests!E12) -> 1997 | E11: =COUNTIF($A$2:$A$501,"<="&A11) -> 447 | F11: =--ISNUMBER(A11) -> 0 | G11: =--(A11="") -> 0 | H11: =IF(ISNUMBER(A11),E11,IF(ISBLANK(A11),E11,E11+$F$502))+$G$502 -> 884 | I11: =IFERROR(INDEX($A$2:$A$501,MATCH(SMALL($H$2:$H$501,ROWS($I$2:I11)+$G$502),$H$2:$H$501,0)),"") -> General Ability Measure for Adults | J11: =IF(I10=I11,J10+1,1) -> 1 | K11: {=INDEX($B$2:$B$501,SMALL(IF($A$2:$A$501=I11,ROW($A$2:$A$501)-ROW(INDEX($A$2:$A$501,1,1))+1),J11))} -> GAMA | L11: {=INDEX($C$2:$C$501,SMALL(IF($A$2:$A$501=I11,ROW($A$2:$A$501)-ROW(INDEX($A$2:$A$501,1,1))+1),J11))} -> 1997 | N11: =IF(K11="","",K11&" ("&L11&")") -> GAMA (1997) | S11: 10 | T11: {=IFERROR(INDEX(A$2:$A$501,MATCH(0,COUNTIF($T$1:T10,A$2:$A$501),0)),"")} -> Naglieri Nonverbal Ability Test | U11: =IFERROR(MATCH(T11,I$2:$I$501,0),"") -> 20 | V11: =COUNTIF(I$2:$I$501,T11) -> 2
A12: =IF(Tests!B13="","",Tests!B13) -> Kaufman Adult and Adolescent Intelligence Test | B12: =IF(Tests!D13="","",Tests!D13) -> KAIT | C12: =IF(Tests!E13="","",Tests!E13) -> 1993 | E12: =COUNTIF($A$2:$A$501,"<="&A12) -> 448 | F12: =--ISNUMBER(A12) -> 0 | G12: =--(A12="") -> 0 | H12: =IF(ISNUMBER(A12),E12,IF(ISBLANK(A12),E12,E12+$F$502))+$G$502 -> 885 | I12: =IFERROR(INDEX($A$2:$A$501,MATCH(SMALL($H$2:$H$501,ROWS($I$2:I12)+$G$502),$H$2:$H$501,0)),"") -> Kaufman Adult and Adolescent Intelligence Test | J12: =IF(I11=I12,J11+1,1) -> 1 | K12: {=INDEX($B$2:$B$501,SMALL(IF($A$2:$A$501=I12,ROW($A$2:$A$501)-ROW(INDEX($A$2:$A$501,1,1))+1),J12))} -> KAIT | L12: {=INDEX($C$2:$C$501,SMALL(IF($A$2:$A$501=I12,ROW($A$2:$A$501)-ROW(INDEX($A$2:$A$501,1,1))+1),J12))} -> 1993 | N12: =IF(K12="","",K12&" ("&L12&")") -> KAIT (1993) | S12: 11 | T12: {=IFERROR(INDEX(A$2:$A$501,MATCH(0,COUNTIF($T$1:T11,A$2:$A$501),0)),"")} -> Reynolds Intellectual Assessment Scales | U12: =IFERROR(MATCH(T12,I$2:$I$501,0),"") -> 22 | V12: =COUNTIF(I$2:$I$501,T12) -> 2
A13: =IF(Tests!B14="","",Tests!B14) -> Kaufman Assessment Battery for Children | B13: =IF(Tests!D14="","",Tests!D14) -> KABC | C13: =IF(Tests!E14="","",Tests!E14) -> 1983 | E13: =COUNTIF($A$2:$A$501,"<="&A13) -> 451 | F13: =--ISNUMBER(A13) -> 0 | G13: =--(A13="") -> 0 | H13: =IF(ISNUMBER(A13),E13,IF(ISBLANK(A13),E13,E13+$F$502))+$G$502 -> 888 | I13: =IFERROR(INDEX($A$2:$A$501,MATCH(SMALL($H$2:$H$501,ROWS($I$2:I13)+$G$502),$H$2:$H$501,0)),"") -> Kaufman Assessment Battery for Children | J13: =IF(I12=I13,J12+1,1) -> 1 | K13: {=INDEX($B$2:$B$501,SMALL(IF($A$2:$A$501=I13,ROW($A$2:$A$501)-ROW(INDEX($A$2:$A$501,1,1))+1),J13))} -> KABC | L13: {=INDEX($C$2:$C$501,SMALL(IF($A$2:$A$501=I13,ROW($A$2:$A$501)-ROW(INDEX($A$2:$A$501,1,1))+1),J13))} -> 1983 | N13: =IF(K13="","",K13&" ("&L13&")") -> KABC (1983) | S13: 12 | T13: {=IFERROR(INDEX(A$2:$A$501,MATCH(0,COUNTIF($T$1:T12,A$2:$A$501),0)),"")} -> Shipley Institute of Living Scale | U13: =IFERROR(MATCH(T13,I$2:$I$501,0),"") -> 24 | V13: =COUNTIF(I$2:$I$501,T13) -> 2
A14: =IF(Tests!B15="","",Tests!B15) -> Kaufman Assessment Battery for Children | B14: =IF(Tests!D15="","",Tests!D15) -> KABC-II | C14: =IF(Tests!E15="","",Tests!E15) -> 2004 | E14: =COUNTIF($A$2:$A$501,"<="&A14) -> 451 | F14: =--ISNUMBER(A14) -> 0 | G14: =--(A14="") -> 0 | H14: =IF(ISNUMBER(A14),E14,IF(ISBLANK(A14),E14,E14+$F$502))+$G$502 -> 888 | I14: =IFERROR(INDEX($A$2:$A$501,MATCH(SMALL($H$2:$H$501,ROWS($I$2:I14)+$G$502),$H$2:$H$501,0)),"") -> Kaufman Assessment Battery for Children | J14: =IF(I13=I14,J13+1,1) -> 2 | K14: {=INDEX($B$2:$B$501,SMALL(IF($A$2:$A$501=I14,ROW($A$2:$A$501)-ROW(INDEX($A$2:$A$501,1,1))+1),J14))} -> KABC-II | L14: {=INDEX($C$2:$C$501,SMALL(IF($A$2:$A$501=I14,ROW($A$2:$A$501)-ROW(INDEX($A$2:$A$501,1,1))+1),J14))} -> 2004 | N14: =IF(K14="","",K14&" ("&L14&")") -> KABC-II (2004) | S14: 13 | T14: {=IFERROR(INDEX(A$2:$A$501,MATCH(0,COUNTIF($T$1:T13,A$2:$A$501),0)),"")} -> Slosson Intelligence Test | U14: =IFERROR(MATCH(T14,I$2:$I$501,0),"") -> 26 | V14: =COUNTIF(I$2:$I$501,T14) -> 5
... A498: =IF(Tests!B499="","",Tests!B499) | B498: =IF(Tests!D499="","",Tests!D499) | C498: =IF(Tests!E499="","",Tests!E499) | E498: =COUNTIF($A$2:$A$501,"<="&A498) -> 0 | F498: =--ISNUMBER(A498) -> 0 | G498: =--(A498="") -> 1 | H498: =IF(ISNUMBER(A498),E498,IF(ISBLANK(A498),E498,E498+$F$502))+$G$502 -> 437 | I498: =IFERROR(INDEX($A$2:$A$501,MATCH(SMALL($H$2:$H$501,ROWS($I$2:I498)+$G$502),$H$2:$H$501,0)),"") | J498: =IF(I497=I498,J497+1,1) -> 434 | K498: {=INDEX($B$2:$B$501,SMALL(IF($A$2:$A$501=I498,ROW($A$2:$A$501)-ROW(INDEX($A$2:$A$501,1,1))+1),J498))} | L498: {=INDEX($C$2:$C$501,SMALL(IF($A$2:$A$501=I498,ROW($A$2:$A$501)-ROW(INDEX($A$2:$A$501,1,1))+1),J498))} | N498: =IF(K498="","",K498&" ("&L498&")") | S498: 497 | T498: {=IFERROR(INDEX(A$2:$A$501,MATCH(0,COUNTIF($T$1:T497,A$2:$A$501),0)),"")} | U498: =IFERROR(MATCH(T498,I$2:$I$501,0),"") -> 64 | V498: =COUNTIF(I$2:$I$501,T498) -> 437
A499: =IF(Tests!B500="","",Tests!B500) | B499: =IF(Tests!D500="","",Tests!D500) | C499: =IF(Tests!E500="","",Tests!E500) | E499: =COUNTIF($A$2:$A$501,"<="&A499) -> 0 | F499: =--ISNUMBER(A499) -> 0 | G499: =--(A499="") -> 1 | H499: =IF(ISNUMBER(A499),E499,IF(ISBLANK(A499),E499,E499+$F$502))+$G$502 -> 437 | I499: =IFERROR(INDEX($A$2:$A$501,MATCH(SMALL($H$2:$H$501,ROWS($I$2:I499)+$G$502),$H$2:$H$501,0)),"") | J499: =IF(I498=I499,J498+1,1) -> 435 | K499: {=INDEX($B$2:$B$501,SMALL(IF($A$2:$A$501=I499,ROW($A$2:$A$501)-ROW(INDEX($A$2:$A$501,1,1))+1),J499))} | L499: {=INDEX($C$2:$C$501,SMALL(IF($A$2:$A$501=I499,ROW($A$2:$A$501)-ROW(INDEX($A$2:$A$501,1,1))+1),J499))} | N499: =IF(K499="","",K499&" ("&L499&")") | S499: 498 | T499: {=IFERROR(INDEX(A$2:$A$501,MATCH(0,COUNTIF($T$1:T498,A$2:$A$501),0)),"")}
A500: =IF(Tests!B501="","",Tests!B501) | B500: =IF(Tests!D501="","",Tests!D501) | C500: =IF(Tests!E501="","",Tests!E501) | E500: =COUNTIF($A$2:$A$501,"<="&A500) -> 0 | F500: =--ISNUMBER(A500) -> 0 | G500: =--(A500="") -> 1 | H500: =IF(ISNUMBER(A500),E500,IF(ISBLANK(A500),E500,E500+$F$502))+$G$502 -> 437 | I500: =IFERROR(INDEX($A$2:$A$501,MATCH(SMALL($H$2:$H$501,ROWS($I$2:I500)+$G$502),$H$2:$H$501,0)),"") | J500: =IF(I499=I500,J499+1,1) -> 436 | K500: {=INDEX($B$2:$B$501,SMALL(IF($A$2:$A$501=I500,ROW($A$2:$A$501)-ROW(INDEX($A$2:$A$501,1,1))+1),J500))} | L500: {=INDEX($C$2:$C$501,SMALL(IF($A$2:$A$501=I500,ROW($A$2:$A$501)-ROW(INDEX($A$2:$A$501,1,1))+1),J500))} | N500: =IF(K500="","",K500&" ("&L500&")") | S500: 499 | T500: {=IFERROR(INDEX(A$2:$A$501,MATCH(0,COUNTIF($T$1:T499,A$2:$A$501),0)),"")}
A501: =IF(Tests!B502="","",Tests!B502) | B501: =IF(Tests!D502="","",Tests!D502) | C501: =IF(Tests!E502="","",Tests!E502) | E501: =COUNTIF($A$2:$A$501,"<="&A501) -> 0 | F501: =--ISNUMBER(A501) -> 0 | G501: =--(A501="") -> 1 | H501: =IF(ISNUMBER(A501),E501,IF(ISBLANK(A501),E501,E501+$F$502))+$G$502 -> 437 | I501: =IFERROR(INDEX($A$2:$A$501,MATCH(SMALL($H$2:$H$501,ROWS($I$2:I501)+$G$502),$H$2:$H$501,0)),"") | J501: =IF(I500=I501,J500+1,1) -> 437 | K501: {=INDEX($B$2:$B$501,SMALL(IF($A$2:$A$501=I501,ROW($A$2:$A$501)-ROW(INDEX($A$2:$A$501,1,1))+1),J501))} | L501: {=INDEX($C$2:$C$501,SMALL(IF($A$2:$A$501=I501,ROW($A$2:$A$501)-ROW(INDEX($A$2:$A$501,1,1))+1),J501))} | N501: =IF(K501="","",K501&" ("&L501&")") | S501: 500 | T501: {=IFERROR(INDEX(A$2:$A$501,MATCH(0,COUNTIF($T$1:T500,A$2:$A$501),0)),"")}
F502: =SUM(F2:F501) -> 0 | G502: =SUM(G2:G501) -> 437

Sheet Blanks
A1: =Main!Y2 -> Correlations | B1: =Main!Z2 -> 1 | C1: =Main!AA2 -> 2 | D1: =Main!AB2 -> 3 | E1: =Main!AC2 -> 4 | F1: =Main!AD2 -> 5 | G1: =Main!AE2 -> 6 | H1: =Main!AF2 -> 7 | ... U1: =Main!AS2 -> 20
A2: =Main!Y3 -> 1. WISC-R (1974) | B2: {=ISBLANK(TRANSPOSE(Main!Z3:AS22))} -> FALSE | C2: TRUE | D2: TRUE | E2: TRUE | F2: TRUE | G2: TRUE | H2: TRUE | I2: TRUE | J2: TRUE | K2: TRUE | L2: TRUE | M2: TRUE | N2: TRUE | O2: TRUE | P2: TRUE | Q2: TRUE | R2: TRUE | S2: TRUE | T2: TRUE | U2: TRUE
A3: =Main!Y4 -> 2. WISC-R (1974) | B3: FALSE | C3: FALSE | D3: TRUE | E3: TRUE | F3: TRUE | G3: TRUE | H3: TRUE | I3: TRUE | J3: TRUE | K3: TRUE | L3: TRUE | M3: TRUE | N3: TRUE | O3: TRUE | P3: TRUE | Q3: TRUE | R3: TRUE | S3: TRUE | T3: TRUE | U3: TRUE
A4: =Main!Y5 -> 3. WAIS-III (1997) | B4: FALSE | C4: FALSE | D4: FALSE | E4: TRUE | F4: TRUE | G4: TRUE | H4: TRUE | I4: TRUE | J4: TRUE | K4: TRUE | L4: TRUE | M4: TRUE | N4: TRUE | O4: TRUE | P4: TRUE | Q4: TRUE | R4: TRUE | S4: TRUE | T4: TRUE | U4: TRUE
A5: =Main!Y6 -> 4. SB5 (2003) | B5: FALSE | C5: FALSE | D5: FALSE | E5: FALSE | F5: TRUE | G5: TRUE | H5: TRUE | I5: TRUE | J5: TRUE | K5: TRUE | L5: TRUE | M5: TRUE | N5: TRUE | O5: TRUE | P5: TRUE | Q5: TRUE | R5: TRUE | S5: TRUE | T5: TRUE | U5: TRUE
A6: =Main!Y7 -> 5. WAIS-IV (2008) | B6: FALSE | C6: FALSE | D6: FALSE | E6: FALSE | F6: FALSE | G6: TRUE | H6: TRUE | I6: TRUE | J6: TRUE | K6: TRUE | L6: TRUE | M6: TRUE | N6: TRUE | O6: TRUE | P6: TRUE | Q6: TRUE | R6: TRUE | S6: TRUE | T6: TRUE | U6: TRUE
A7: =Main!Y8 -> 6 | B7: FALSE | C7: FALSE | D7: FALSE | E7: FALSE | F7: FALSE | G7: FALSE | H7: TRUE | I7: TRUE | J7: TRUE | K7: TRUE | L7: TRUE | M7: TRUE | N7: TRUE | O7: TRUE | P7: TRUE | Q7: TRUE | R7: TRUE | S7: TRUE | T7: TRUE | U7: TRUE
A8: =Main!Y9 -> 7 | B8: FALSE | C8: FALSE | D8: FALSE | E8: FALSE | F8: FALSE | G8: FALSE | H8: FALSE | I8: TRUE | J8: TRUE | K8: TRUE | L8: TRUE | M8: TRUE | N8: TRUE | O8: TRUE | P8: TRUE | Q8: TRUE | R8: TRUE | S8: TRUE | T8: TRUE | U8: TRUE
A9: =Main!Y10 -> 8 | B9: FALSE | C9: FALSE | D9: FALSE | E9: FALSE | F9: FALSE | G9: FALSE | H9: FALSE | I9: FALSE | J9: TRUE | K9: TRUE | L9: TRUE | M9: TRUE | N9: TRUE | O9: TRUE | P9: TRUE | Q9: TRUE | R9: TRUE | S9: TRUE | T9: TRUE | U9: TRUE
A10: =Main!Y11 -> 9 | B10: FALSE | C10: FALSE | D10: FALSE | E10: FALSE | F10: FALSE | G10: FALSE | H10: FALSE | I10: FALSE | J10: FALSE | K10: TRUE | L10: TRUE | M10: TRUE | N10: TRUE | O10: TRUE | P10: TRUE | Q10: TRUE | R10: TRUE | S10: TRUE | T10: TRUE | U10: TRUE
A11: =Main!Y12 -> 10 | B11: FALSE | C11: FALSE | D11: FALSE | E11: FALSE | F11: FALSE | G11: FALSE | H11: FALSE | I11: FALSE | J11: FALSE | K11: FALSE | L11: TRUE | M11: TRUE | N11: TRUE | O11: TRUE | P11: TRUE | Q11: TRUE | R11: TRUE | S11: TRUE | T11: TRUE | U11: TRUE
A12: =Main!Y13 -> 11 | B12: FALSE | C12: FALSE | D12: FALSE | E12: FALSE | F12: FALSE | G12: FALSE | H12: FALSE | I12: FALSE | J12: FALSE | K12: FALSE | L12: FALSE | M12: TRUE | N12: TRUE | O12: TRUE | P12: TRUE | Q12: TRUE | R12: TRUE | S12: TRUE | T12: TRUE | U12: TRUE
A13: =Main!Y14 -> 12 | B13: FALSE | C13: FALSE | D13: FALSE | E13: FALSE | F13: FALSE | G13: FALSE | H13: FALSE | I13: FALSE | J13: FALSE | K13: FALSE | L13: FALSE | M13: FALSE | N13: TRUE | O13: TRUE | P13: TRUE | Q13: TRUE | R13: TRUE | S13: TRUE | T13: TRUE | U13: TRUE
A14: =Main!Y15 -> 13 | B14: FALSE | C14: FALSE | D14: FALSE | E14: FALSE | F14: FALSE | G14: FALSE | H14: FALSE | I14: FALSE | J14: FALSE | K14: FALSE | L14: FALSE | M14: FALSE | N14: FALSE | O14: TRUE | P14: TRUE | Q14: TRUE | R14: TRUE | S14: TRUE | T14: TRUE | U14: TRUE
... A21: =Main!Y22 -> 20 | B21: FALSE | C21: FALSE | D21: FALSE | E21: FALSE | F21: FALSE | G21: FALSE | H21: FALSE | I21: FALSE | J21: FALSE | K21: FALSE | L21: FALSE | M21: FALSE | N21: FALSE | O21: FALSE | P21: FALSE | Q21: FALSE | R21: FALSE | S21: FALSE | T21: FALSE | U21: FALSE
A24: Include | B24: {=TRANSPOSE(A25:A44)} -> FALSE | C24: FALSE | D24: FALSE | E24: FALSE | F24: FALSE | G24: TRUE | H24: TRUE | I24: TRUE | J24: TRUE | K24: TRUE | L24: TRUE | M24: TRUE | N24: TRUE | O24: TRUE | P24: TRUE | Q24: TRUE | R24: TRUE | S24: TRUE | T24: TRUE | U24: TRUE
A25: =Calculations!Z11="" -> FALSE | B25: {=(A25:A44+B24:U24)>0} -> FALSE | C25: FALSE | D25: FALSE | E25: FALSE | F25: FALSE | G25: TRUE | H25: TRUE | I25: TRUE | J25: TRUE | K25: TRUE | L25: TRUE | M25: TRUE | N25: TRUE | O25: TRUE | P25: TRUE | Q25: TRUE | R25: TRUE | S25: TRUE | T25: TRUE | U25: TRUE
A26: =Calculations!Z12="" -> FALSE | B26: FALSE | C26: FALSE | D26: FALSE | E26: FALSE | F26: FALSE | G26: TRUE | H26: TRUE | I26: TRUE | J26: TRUE | K26: TRUE | L26: TRUE | M26: TRUE | N26: TRUE | O26: TRUE | P26: TRUE | Q26: TRUE | R26: TRUE | S26: TRUE | T26: TRUE | U26: TRUE
A27: =Calculations!Z13="" -> FALSE | B27: FALSE | C27: FALSE | D27: FALSE | E27: FALSE | F27: FALSE | G27: TRUE | H27: TRUE | I27: TRUE | J27: TRUE | K27: TRUE | L27: TRUE | M27: TRUE | N27: TRUE | O27: TRUE | P27: TRUE | Q27: TRUE | R27: TRUE | S27: TRUE | T27: TRUE | U27: TRUE
A28: =Calculations!Z14="" -> FALSE | B28: FALSE | C28: FALSE | D28: FALSE | E28: FALSE | F28: FALSE | G28: TRUE | H28: TRUE | I28: TRUE | J28: TRUE | K28: TRUE | L28: TRUE | M28: TRUE | N28: TRUE | O28: TRUE | P28: TRUE | Q28: TRUE | R28: TRUE | S28: TRUE | T28: TRUE | U28: TRUE
